<mujoco model="bd1 scene">
	<option timestep="0.005"/>

	<compiler angle="radian" autolimits="true"/>

	<asset>
		<mesh name="base" file="base.stl"/>
		<mesh name="dc11_a01_spacer_dummy" file="dc11_a01_spacer_dummy.stl"/>
		<mesh name="dc11_a01_dummy" file="dc11_a01_dummy.stl"/>
		<mesh name="rotation_connector" file="rotation_connector.stl"/>
		<mesh name="arm_connector" file="arm_connector.stl"/>
		<mesh name="dc15_a01_horn_idle2_dummy" file="dc15_a01_horn_idle2_dummy.stl"/>
		<mesh name="dc15_a01_case_m_dummy" file="dc15_a01_case_m_dummy.stl"/>
		<mesh name="dc15_a01_case_f_dummy" file="dc15_a01_case_f_dummy.stl"/>
		<mesh name="dc15_a01_horn_dummy" file="dc15_a01_horn_dummy.stl"/>
		<mesh name="dc15_a01_case_b_dummy" file="dc15_a01_case_b_dummy.stl"/>
		<mesh name="connector" file="connector.stl"/>
		<mesh name="shoulder_rotation" file="shoulder_rotation.stl"/>
		<mesh name="static_side" file="static_side.stl"/>
		<mesh name="moving_side" file="moving_side.stl"/>
		<texture type="skybox" builtin="gradient" rgb1="0.3 0.5 0.7" rgb2="0 0 0" width="512" height="3072" />
		<texture type="2d" name="groundplane" builtin="checker" mark="edge" rgb1="0.2 0.3 0.4" rgb2="0.1 0.2 0.3" markrgb="0.8 0.8 0.8" width="300" height="300" />
		<material name="groundplane" texture="groundplane" texuniform="true" texrepeat="5 5" reflectance="0.2" />
	</asset>

	<visual>
		<headlight diffuse="0.6 0.6 0.6" ambient="0.3 0.3 0.3" specular="0 0 0" />
		<rgba haze="0.15 0.25 0.35 1" />
		<global azimuth="150" elevation="-20" offheight="640" />
	</visual>

	<worldbody>
		<light pos="0 0 3" dir="0 0 -1" directional="false" />
		<body name="floor">
			<geom pos="0 0 0" name="floor" size="0 0 .125" type="plane" material="groundplane" conaffinity="1" contype="1" />
		</body>

		<body name="cube_red" pos="0.1 0.1 0.01">
			<freejoint name="cube_red"/>
			<inertial pos="0 0 0" mass="0.1" diaginertia="0.00001125 0.00001125 0.00001125"/>
			<geom friction="0.5" condim="3" pos="0 0 0" size="0.015 0.015 0.015" type="box" name="cube_red" rgba="0.5 0 0 1" priority="1"/>
		</body>

		<body name="cube_blue" pos="-0.1 -0.1 0.01">
			<freejoint name="cube_blue"/>
			<inertial pos="0 0 0" mass="0.1" diaginertia="0.00001125 0.00001125 0.00001125"/>
			<geom friction="0.5" condim="3" pos="0 0 0" size="0.015 0.015 0.015" type="box" name="cube_blue" rgba="0 0 0.5 1" priority="1"/>
		</body>


		<camera name="camera_front" pos="0.049 0.888 0.317" xyaxes="-0.998 0.056 -0.000 -0.019 -0.335 0.942"/>
		<camera name="camera_top" pos="0 0 1" euler="0 0 0" mode="fixed"/>
		<camera name="camera_vizu" pos="-0.1 0.6 0.3" quat="-0.15 -0.1 0.6 1"/>
		
		<geom pos="0.0401555 -0.0353754 -0.0242427" type="mesh" rgba="0.647059 0.647059 0.647059 1" mesh="base"/>
		<geom pos="0.0511555 0.0406246 0.0099573" quat="0 0 0 1" type="mesh" rgba="0.647059 0.647059 0.647059 1" mesh="dc11_a01_spacer_dummy"/>
		<geom pos="0.0291555 0.000624643 0.0099573" quat="0 0 0 1" type="mesh" rgba="0.647059 0.647059 0.647059 1" mesh="dc11_a01_spacer_dummy"/>
		<geom pos="0.0511555 0.000624643 -0.0184427" quat="0 0 1 0" type="mesh" rgba="0.647059 0.647059 0.647059 1" mesh="dc11_a01_spacer_dummy"/>
		<geom pos="0.0401555 0.0326246 -0.0042427" type="mesh" rgba="0.498039 0.498039 0.498039 1" mesh="dc11_a01_dummy"/>
		<geom pos="0.0291555 0.000624643 -0.0184427" quat="0 0.707107 0.707107 0" type="mesh" rgba="0.647059 0.647059 0.647059 1" mesh="dc11_a01_spacer_dummy"/>
		<geom pos="0.0291555 0.0406246 0.0099573" quat="0.707107 0 0 -0.707107" type="mesh" rgba="0.647059 0.647059 0.647059 1" mesh="dc11_a01_spacer_dummy"/>
		<geom pos="0.0511555 0.0406246 -0.0184427" quat="0 0.707107 -0.707107 0" type="mesh" rgba="0.647059 0.647059 0.647059 1" mesh="dc11_a01_spacer_dummy"/>
		<geom pos="0.0291555 0.0406246 -0.0184427" quat="0 -1 0 0" type="mesh" rgba="0.647059 0.647059 0.647059 1" mesh="dc11_a01_spacer_dummy"/>
		<geom pos="0.0511555 0.000624643 0.0099573" quat="0.707107 0 0 0.707107" type="mesh" rgba="0.647059 0.647059 0.647059 1" mesh="dc11_a01_spacer_dummy"/>

		<body name="pitch1_assembly" pos="0.0401555 0.0326246 0.0166573">

			<inertial pos="-0.000767103 -0.0121505 0.0134241" quat="0.498429 0.53272 -0.473938 0.493113" mass="0.0606831" diaginertia="1.86261e-05 1.72746e-05 1.11693e-05"/>
			<joint name="shoulder_pan_joint" pos="0 0 0" axis="0 0 1" range="-3.14159 3.14159" damping="0.1" actuatorfrcrange="-0.5 0.5" actuatorfrclimited="true"/>
			<geom pos="0 0 -0.0209" type="mesh" rgba="0.231373 0.380392 0.705882 1" mesh="rotation_connector"/>
			<geom pos="-0.014 0.008 0.0264" quat="0 -0.707107 0 0.707107" type="mesh" rgba="0.647059 0.647059 0.647059 1" mesh="dc11_a01_spacer_dummy"/>
			<geom pos="-0.014 -0.032 0.0044" quat="0 -0.707107 0 0.707107" type="mesh" rgba="0.647059 0.647059 0.647059 1" mesh="dc11_a01_spacer_dummy"/>
			<geom pos="0.0144 -0.032 0.0264" quat="0.707107 0 0.707107 0" type="mesh" rgba="0.647059 0.647059 0.647059 1" mesh="dc11_a01_spacer_dummy"/>
			<geom pos="0.0002 0 0.0154" quat="0.707107 0 -0.707107 0" type="mesh" rgba="0.498039 0.498039 0.498039 1" mesh="dc11_a01_dummy"/>
			<geom pos="0.0144 -0.032 0.0044" quat="0.5 0.5 0.5 0.5" type="mesh" rgba="0.647059 0.647059 0.647059 1" mesh="dc11_a01_spacer_dummy"/>
			<geom pos="-0.014 0.008 0.0044" quat="0.5 0.5 -0.5 -0.5" type="mesh" rgba="0.647059 0.647059 0.647059 1" mesh="dc11_a01_spacer_dummy"/>
			<geom pos="0.0144 0.008 0.0264" quat="0.5 -0.5 0.5 -0.5" type="mesh" rgba="0.647059 0.647059 0.647059 1" mesh="dc11_a01_spacer_dummy"/>
			<geom pos="0.0144 0.008 0.0044" quat="0 0.707107 0 0.707107" type="mesh" rgba="0.647059 0.647059 0.647059 1" mesh="dc11_a01_spacer_dummy"/>
			<geom pos="-0.014 -0.032 0.0264" quat="0.5 -0.5 -0.5 0.5" type="mesh" rgba="0.647059 0.647059 0.647059 1" mesh="dc11_a01_spacer_dummy"/>

			<body name="pitch2_assembly" pos="-0.0188 0 0.0154" quat="0 0.707107 0 0.707107">

				<inertial pos="0.0766242 -0.00031229 0.0187402" quat="0.52596 0.513053 0.489778 0.469319" mass="0.0432446" diaginertia="7.21796e-05 7.03107e-05 1.07533e-05"/>
				<joint name="shoulder_lift_joint" pos="0 0 0" axis="0 0 1" range="-1.5708 1.22173" damping="0.1" actuatorfrcrange="-0.5 0.5" actuatorfrclimited="true"/>
				<geom pos="0 0 0.019" quat="0.5 -0.5 -0.5 -0.5" type="mesh" rgba="0.980392 0.713726 0.00392157 1" mesh="arm_connector"/>
				<geom pos="0.1083 -0.0148 0.03035" quat="1 0 0 0" type="mesh" rgba="0.647059 0.647059 0.647059 1" mesh="dc15_a01_horn_idle2_dummy"/>
				<geom pos="0.1083 -0.0148 0.01075" quat="0 -1 0 0" type="mesh" rgba="0.615686 0.811765 0.929412 1" mesh="dc15_a01_case_m_dummy"/>
				<geom pos="0.1083 -0.0148 0.01075" quat="0 -1 0 0" type="mesh" rgba="0.980392 0.713726 0.00392157 1" mesh="dc15_a01_case_f_dummy"/>
				<geom pos="0.1083 -0.0148 0.00715" quat="0 0 0.707107 -0.707107" type="mesh" rgba="0.972549 0.529412 0.00392157 1" mesh="dc15_a01_horn_dummy"/>
				<geom pos="0.1083 -0.0148 0.03025" quat="0 -1 0 0" type="mesh" rgba="0.498039 0.498039 0.498039 1" mesh="dc15_a01_case_b_dummy"/>

				<body name="pitch3_assembly" pos="0.1083 -0.0148 0.00425" quat="0.707107 0 0 0.707107">
					<inertial pos="-0.0551014 -0.00287792 0.0144813" quat="0.500323 0.499209 0.499868 0.5006" mass="0.0788335" diaginertia="6.80912e-05 6.45748e-05 9.84479e-06"/>
					<joint name="elbow_flex_joint" pos="0 0 0" axis="0 0 1" range="-1.48353 1.74533"  damping="0.1" actuatorfrcrange="-0.5 0.5" actuatorfrclimited="true"/>
					<geom pos="-0.00863031 0.00847376 0.0145" quat="0.5 0.5 0.5 -0.5" type="mesh" rgba="0.615686 0.811765 0.929412 1" mesh="connector"/>
					<geom pos="-0.100476 -0.00269986 0.02635" quat="0.707107 0 0 -0.707107" type="mesh" rgba="0.647059 0.647059 0.647059 1" mesh="dc15_a01_horn_idle2_dummy"/>
					<geom pos="-0.100476 -0.00269986 0.00675" quat="0 -0.707107 0.707107 0" type="mesh" rgba="0.615686 0.811765 0.929412 1" mesh="dc15_a01_case_m_dummy"/>
					<geom pos="-0.100476 -0.00269986 0.00675" quat="0 -0.707107 0.707107 0" type="mesh" rgba="0.980392 0.713726 0.00392157 1" mesh="dc15_a01_case_f_dummy"/>
					<geom pos="-0.100476 -0.00269986 0.00315" quat="0.5 -0.5 -0.5 0.5" type="mesh" rgba="0.972549 0.529412 0.00392157 1" mesh="dc15_a01_horn_dummy"/>
					<geom pos="-0.100476 -0.00269986 0.02625" quat="0 -0.707107 0.707107 0" type="mesh" rgba="0.498039 0.498039 0.498039 1" mesh="dc15_a01_case_b_dummy"/>

					<body name="effector_roll_assembly" pos="-0.100476 -0.00269986 0.02925" quat="0 -0.707107 -0.707107 0">
						<inertial pos="-1.65017e-05 -0.02659 0.0195388" quat="0.936813 0.349829 -0.00055331 -0.000300569" mass="0.0240506" diaginertia="6.03208e-06 4.12894e-06 3.3522e-06"/>
						<joint name="wrist_flex_joint" pos="0 0 0" axis="0 0 1" range="-1.91986 1.91986"  damping="0.1" actuatorfrcrange="-0.5 0.5" actuatorfrclimited="true"/>
						<geom pos="-0.0109998 -0.0190002 0.039" quat="0.707107 -0.707107 0 0" type="mesh" rgba="0.615686 0.811765 0.929412 1" mesh="shoulder_rotation"/>
						<geom pos="-7.44154e-06 -0.0385002 0.0133967" quat="0 0 0.707107 -0.707107" type="mesh" rgba="0.615686 0.811765 0.929412 1" mesh="dc15_a01_case_m_dummy"/>
						<geom pos="-7.44154e-06 -0.0385002 0.0133967" quat="0 0 0.707107 -0.707107" type="mesh" rgba="0.980392 0.713726 0.00392157 1" mesh="dc15_a01_case_f_dummy"/>
						<geom pos="-7.44154e-06 -0.0421002 0.0133967" quat="0 1 0 0" type="mesh" rgba="0.972549 0.529412 0.00392157 1" mesh="dc15_a01_horn_dummy"/>
						<geom pos="-7.44154e-06 -0.0190002 0.0133967" quat="0 0 0.707107 -0.707107" type="mesh" rgba="0.498039 0.498039 0.498039 1" mesh="dc15_a01_case_b_dummy"/>

						<body name="gripper_assembly" pos="-7.44154e-06 -0.0450002 0.0133967" quat="0.5 -0.5 -0.5 -0.5">
							<inertial pos="-0.00548595 -0.000433143 -0.0190793" quat="0.700194 0.164851 0.167361 0.674197" mass="0.0360627" diaginertia="1.3261e-05 1.231e-05 5.3532e-06"/>
							<joint name="wrist_roll_joint" pos="0 0 0" axis="0 0 1" range="-2.96706 2.96706"  damping="0.1" actuatorfrcrange="-0.5 0.5" actuatorfrclimited="true"/>
							<geom pos="-0.00075 -0.01475 -0.02" quat="0.707107 -0.707107 0 0" type="mesh" rgba="0.917647 0.917647 0.917647 1" mesh="static_side"/>
							<geom pos="0.00755 0.01135 -0.013" quat="0.5 -0.5 0.5 0.5" type="mesh" rgba="0.647059 0.647059 0.647059 1" mesh="dc15_a01_horn_idle2_dummy"/>
							<geom pos="0.00755 -0.00825 -0.013" quat="0.5 0.5 0.5 -0.5" type="mesh" rgba="0.615686 0.811765 0.929412 1" mesh="dc15_a01_case_m_dummy"/>
							<geom pos="0.00755 -0.00825 -0.013" quat="0.5 0.5 0.5 -0.5" type="mesh" rgba="0.980392 0.713726 0.00392157 1" mesh="dc15_a01_case_f_dummy"/>
							<geom pos="0.00755 -0.01185 -0.013" quat="0 -0.707107 0 -0.707107" type="mesh" rgba="0.972549 0.529412 0.00392157 1" mesh="dc15_a01_horn_dummy"/>
							<geom pos="0.00755 0.01125 -0.013" quat="0.5 0.5 0.5 -0.5" type="mesh" rgba="0.498039 0.498039 0.498039 1" mesh="dc15_a01_case_b_dummy"/>

							<body name="moving_side" pos="0.00755 -0.01475 -0.013" quat="0.707107 -0.707107 0 0">
								<inertial pos="-0.000395599 0.022415 0.0145636" quat="0.722353 0.689129 0.0389102 0.0423547" mass="0.0089856" diaginertia="3.28451e-06 2.24898e-06 1.41539e-06"/>
								<joint name="gripper_joint" pos="0 0 0" axis="0 0 1" range="-1.74533 0.0523599"  damping="0.1" actuatorfrcrange="-0.5 0.5" actuatorfrclimited="true"/>
								<geom pos="-0.00838199 -0.000256591 -0.003" type="mesh" rgba="0.768627 0.886275 0.952941 1" mesh="moving_side"/>
							</body>
						</body>
					</body>
				</body>
			</body>
		</body>
	</worldbody>

	<actuator>
		<position joint="shoulder_pan_joint" ctrlrange="-3.14159 3.14159" ctrllimited="true" kp="20" />
		<position joint="shoulder_lift_joint" ctrlrange="-1.5708 1.22173" ctrllimited="true" kp="20" />
		<position joint="elbow_flex_joint" ctrlrange="-1.48353 1.74533" ctrllimited="true" kp="20" />
		<position joint="wrist_flex_joint" ctrlrange="-1.91986 1.91986" ctrllimited="true" kp="20" />
		<position joint="wrist_roll_joint" ctrlrange="-2.96706 2.96706" ctrllimited="true" kp="20" />
		<position joint="gripper_joint" ctrlrange="-1.74533 0.0523599" ctrllimited="true" kp="20" />
	</actuator>
</mujoco>
